[2018-08-31 17:41:17,943]-result.py:58-ERROR - OrderList error:Traceback (most recent call last):
  File "/Users/shuai.chen/eclipse-workspace/app-breeding/app/common/result.py", line 53, in __deco
    return func(self)
  File "/Users/shuai.chen/eclipse-workspace/app-breeding/app/handlers/user.py", line 416, in _post
    orders = user_goods_service.gets(user_id=self.user.id)
  File "/Users/shuai.chen/eclipse-workspace/app-breeding/base/cache.py", line 25, in __deco
    obj = self.cache.get_obj(key)
  File "/Users/shuai.chen/pyenv/lib/python2.7/site-packages/towgo-1.0.0-py2.7.egg/towgo/cache/db_cache.py", line 77, in get_obj
    val = self.conn.get(key)
  File "build/bdist.macosx-10.6-intel/egg/redis/client.py", line 880, in get
    return self.execute_command('GET', name)
  File "build/bdist.macosx-10.6-intel/egg/redis/client.py", line 578, in execute_command
    connection.send_command(*args)
  File "build/bdist.macosx-10.6-intel/egg/redis/connection.py", line 563, in send_command
    self.send_packed_command(self.pack_command(*args))
  File "build/bdist.macosx-10.6-intel/egg/redis/connection.py", line 538, in send_packed_command
    self.connect()
  File "build/bdist.macosx-10.6-intel/egg/redis/connection.py", line 442, in connect
    raise ConnectionError(self._error_message(e))
ConnectionError: Error 61 connecting to 192.168.1.165:6381. Connection refused.

[2018-08-31 17:41:23,124]-result.py:58-ERROR - OrderList error:Traceback (most recent call last):
  File "/Users/shuai.chen/eclipse-workspace/app-breeding/app/common/result.py", line 53, in __deco
    return func(self)
  File "/Users/shuai.chen/eclipse-workspace/app-breeding/app/handlers/user.py", line 416, in _post
    orders = user_goods_service.gets(user_id=self.user.id)
  File "/Users/shuai.chen/eclipse-workspace/app-breeding/base/cache.py", line 25, in __deco
    obj = self.cache.get_obj(key)
  File "/Users/shuai.chen/pyenv/lib/python2.7/site-packages/towgo-1.0.0-py2.7.egg/towgo/cache/db_cache.py", line 77, in get_obj
    val = self.conn.get(key)
  File "build/bdist.macosx-10.6-intel/egg/redis/client.py", line 880, in get
    return self.execute_command('GET', name)
  File "build/bdist.macosx-10.6-intel/egg/redis/client.py", line 578, in execute_command
    connection.send_command(*args)
  File "build/bdist.macosx-10.6-intel/egg/redis/connection.py", line 563, in send_command
    self.send_packed_command(self.pack_command(*args))
  File "build/bdist.macosx-10.6-intel/egg/redis/connection.py", line 538, in send_packed_command
    self.connect()
  File "build/bdist.macosx-10.6-intel/egg/redis/connection.py", line 442, in connect
    raise ConnectionError(self._error_message(e))
ConnectionError: Error 61 connecting to 192.168.1.165:6381. Connection refused.

[2018-08-31 17:41:27,414]-result.py:58-ERROR - OrderList error:Traceback (most recent call last):
  File "/Users/shuai.chen/eclipse-workspace/app-breeding/app/common/result.py", line 53, in __deco
    return func(self)
  File "/Users/shuai.chen/eclipse-workspace/app-breeding/app/handlers/user.py", line 416, in _post
    orders = user_goods_service.gets(user_id=self.user.id)
  File "/Users/shuai.chen/eclipse-workspace/app-breeding/base/cache.py", line 25, in __deco
    obj = self.cache.get_obj(key)
  File "/Users/shuai.chen/pyenv/lib/python2.7/site-packages/towgo-1.0.0-py2.7.egg/towgo/cache/db_cache.py", line 77, in get_obj
    val = self.conn.get(key)
  File "build/bdist.macosx-10.6-intel/egg/redis/client.py", line 880, in get
    return self.execute_command('GET', name)
  File "build/bdist.macosx-10.6-intel/egg/redis/client.py", line 578, in execute_command
    connection.send_command(*args)
  File "build/bdist.macosx-10.6-intel/egg/redis/connection.py", line 563, in send_command
    self.send_packed_command(self.pack_command(*args))
  File "build/bdist.macosx-10.6-intel/egg/redis/connection.py", line 538, in send_packed_command
    self.connect()
  File "build/bdist.macosx-10.6-intel/egg/redis/connection.py", line 442, in connect
    raise ConnectionError(self._error_message(e))
ConnectionError: Error 61 connecting to 192.168.1.165:6381. Connection refused.

[2018-08-31 17:56:54,084]-result.py:58-ERROR - OrderList error:Traceback (most recent call last):
  File "/Users/shuai.chen/eclipse-workspace/app-breeding/app/common/result.py", line 53, in __deco
    return func(self)
  File "/Users/shuai.chen/eclipse-workspace/app-breeding/app/handlers/user.py", line 416, in _post
    orders = user_goods_service.gets(user_id=self.user.id)
  File "/Users/shuai.chen/eclipse-workspace/app-breeding/base/cache.py", line 25, in __deco
    obj = self.cache.get_obj(key)
  File "/Users/shuai.chen/pyenv/lib/python2.7/site-packages/towgo-1.0.0-py2.7.egg/towgo/cache/db_cache.py", line 77, in get_obj
    val = self.conn.get(key)
  File "build/bdist.macosx-10.6-intel/egg/redis/client.py", line 880, in get
    return self.execute_command('GET', name)
  File "build/bdist.macosx-10.6-intel/egg/redis/client.py", line 578, in execute_command
    connection.send_command(*args)
  File "build/bdist.macosx-10.6-intel/egg/redis/connection.py", line 563, in send_command
    self.send_packed_command(self.pack_command(*args))
  File "build/bdist.macosx-10.6-intel/egg/redis/connection.py", line 538, in send_packed_command
    self.connect()
  File "build/bdist.macosx-10.6-intel/egg/redis/connection.py", line 442, in connect
    raise ConnectionError(self._error_message(e))
ConnectionError: Error 61 connecting to 192.168.1.165:6381. Connection refused.

[2018-08-31 17:56:56,406]-result.py:58-ERROR - OrderList error:Traceback (most recent call last):
  File "/Users/shuai.chen/eclipse-workspace/app-breeding/app/common/result.py", line 53, in __deco
    return func(self)
  File "/Users/shuai.chen/eclipse-workspace/app-breeding/app/handlers/user.py", line 416, in _post
    orders = user_goods_service.gets(user_id=self.user.id)
  File "/Users/shuai.chen/eclipse-workspace/app-breeding/base/cache.py", line 25, in __deco
    obj = self.cache.get_obj(key)
  File "/Users/shuai.chen/pyenv/lib/python2.7/site-packages/towgo-1.0.0-py2.7.egg/towgo/cache/db_cache.py", line 77, in get_obj
    val = self.conn.get(key)
  File "build/bdist.macosx-10.6-intel/egg/redis/client.py", line 880, in get
    return self.execute_command('GET', name)
  File "build/bdist.macosx-10.6-intel/egg/redis/client.py", line 578, in execute_command
    connection.send_command(*args)
  File "build/bdist.macosx-10.6-intel/egg/redis/connection.py", line 563, in send_command
    self.send_packed_command(self.pack_command(*args))
  File "build/bdist.macosx-10.6-intel/egg/redis/connection.py", line 538, in send_packed_command
    self.connect()
  File "build/bdist.macosx-10.6-intel/egg/redis/connection.py", line 442, in connect
    raise ConnectionError(self._error_message(e))
ConnectionError: Error 61 connecting to 192.168.1.165:6381. Connection refused.

[2018-08-31 18:02:44,102]-result.py:58-ERROR - OrderList error:Traceback (most recent call last):
  File "/Users/shuai.chen/eclipse-workspace/app-breeding/app/common/result.py", line 53, in __deco
    return func(self)
  File "/Users/shuai.chen/eclipse-workspace/app-breeding/app/handlers/user.py", line 416, in _post
    orders = user_goods_service.gets(user_id=self.user.id)
  File "/Users/shuai.chen/eclipse-workspace/app-breeding/base/cache.py", line 25, in __deco
    obj = self.cache.get_obj(key)
  File "/Users/shuai.chen/pyenv/lib/python2.7/site-packages/towgo-1.0.0-py2.7.egg/towgo/cache/db_cache.py", line 77, in get_obj
    val = self.conn.get(key)
  File "build/bdist.macosx-10.6-intel/egg/redis/client.py", line 880, in get
    return self.execute_command('GET', name)
  File "build/bdist.macosx-10.6-intel/egg/redis/client.py", line 579, in execute_command
    return self.parse_response(connection, command_name, **options)
  File "build/bdist.macosx-10.6-intel/egg/redis/client.py", line 585, in parse_response
    response = connection.read_response()
  File "build/bdist.macosx-10.6-intel/egg/redis/connection.py", line 577, in read_response
    response = self._parser.read_response()
  File "build/bdist.macosx-10.6-intel/egg/redis/connection.py", line 255, in read_response
    raise error
BusyLoadingError: Redis is loading the dataset in memory

